INFO:werkzeug:[31m[1mWARNING: This is a development server. Do not use it in a production deployment. Use a production WSGI server instead.[0m
 * Running on all addresses (0.0.0.0)
 * Running on http://127.0.0.1:8000
 * Running on http://10.8.0.6:8000
INFO:werkzeug:[33mPress CTRL+C to quit[0m
INFO:werkzeug:127.0.0.1 - - [16/Jun/2024 23:42:55] "GET / HTTP/1.1" 200 -
INFO:werkzeug:127.0.0.1 - - [16/Jun/2024 23:42:55] "GET /static/styles.css HTTP/1.1" 200 -
ERROR:main:Exception on /favicon.ico [GET]
Traceback (most recent call last):
  File "/Users/hiroshimatakara/Desktop/app/venv/lib/python3.9/site-packages/flask/app.py", line 880, in full_dispatch_request
    rv = self.dispatch_request()
  File "/Users/hiroshimatakara/Desktop/app/venv/lib/python3.9/site-packages/flask/app.py", line 854, in dispatch_request
    self.raise_routing_exception(req)
  File "/Users/hiroshimatakara/Desktop/app/venv/lib/python3.9/site-packages/flask/app.py", line 463, in raise_routing_exception
    raise request.routing_exception  # type: ignore[misc]
  File "/Users/hiroshimatakara/Desktop/app/venv/lib/python3.9/site-packages/flask/ctx.py", line 362, in match_request
    result = self.url_adapter.match(return_rule=True)  # type: ignore
  File "/Users/hiroshimatakara/Desktop/app/venv/lib/python3.9/site-packages/werkzeug/routing/map.py", line 629, in match
    raise NotFound() from None
werkzeug.exceptions.NotFound: 404 Not Found: The requested URL was not found on the server. If you entered the URL manually please check your spelling and try again.

During handling of the above exception, another exception occurred:

Traceback (most recent call last):
  File "/Users/hiroshimatakara/Desktop/app/venv/lib/python3.9/site-packages/flask/app.py", line 1473, in wsgi_app
    response = self.full_dispatch_request()
  File "/Users/hiroshimatakara/Desktop/app/venv/lib/python3.9/site-packages/flask/app.py", line 882, in full_dispatch_request
    rv = self.handle_user_exception(e)
  File "/Users/hiroshimatakara/Desktop/app/venv/lib/python3.9/site-packages/flask/app.py", line 765, in handle_user_exception
    return self.handle_http_exception(e)
  File "/Users/hiroshimatakara/Desktop/app/venv/lib/python3.9/site-packages/flask/app.py", line 740, in handle_http_exception
    return self.ensure_sync(handler)(e)  # type: ignore[no-any-return]
  File "/Users/hiroshimatakara/Desktop/app/main.py", line 666, in handle_exception
    return jsonify(response), 500
TypeError: 'module' object is not callable
INFO:werkzeug:127.0.0.1 - - [16/Jun/2024 23:42:55] "[35m[1mGET /favicon.ico HTTP/1.1[0m" 500 -
ERROR:werkzeug:Error on request:
Traceback (most recent call last):
  File "/Users/hiroshimatakara/Desktop/app/venv/lib/python3.9/site-packages/flask/app.py", line 880, in full_dispatch_request
    rv = self.dispatch_request()
  File "/Users/hiroshimatakara/Desktop/app/venv/lib/python3.9/site-packages/flask/app.py", line 854, in dispatch_request
    self.raise_routing_exception(req)
  File "/Users/hiroshimatakara/Desktop/app/venv/lib/python3.9/site-packages/flask/app.py", line 463, in raise_routing_exception
    raise request.routing_exception  # type: ignore[misc]
  File "/Users/hiroshimatakara/Desktop/app/venv/lib/python3.9/site-packages/flask/ctx.py", line 362, in match_request
    result = self.url_adapter.match(return_rule=True)  # type: ignore
  File "/Users/hiroshimatakara/Desktop/app/venv/lib/python3.9/site-packages/werkzeug/routing/map.py", line 629, in match
    raise NotFound() from None
werkzeug.exceptions.NotFound: 404 Not Found: The requested URL was not found on the server. If you entered the URL manually please check your spelling and try again.

During handling of the above exception, another exception occurred:

Traceback (most recent call last):
  File "/Users/hiroshimatakara/Desktop/app/venv/lib/python3.9/site-packages/flask/app.py", line 1473, in wsgi_app
    response = self.full_dispatch_request()
  File "/Users/hiroshimatakara/Desktop/app/venv/lib/python3.9/site-packages/flask/app.py", line 882, in full_dispatch_request
    rv = self.handle_user_exception(e)
  File "/Users/hiroshimatakara/Desktop/app/venv/lib/python3.9/site-packages/flask/app.py", line 765, in handle_user_exception
    return self.handle_http_exception(e)
  File "/Users/hiroshimatakara/Desktop/app/venv/lib/python3.9/site-packages/flask/app.py", line 740, in handle_http_exception
    return self.ensure_sync(handler)(e)  # type: ignore[no-any-return]
  File "/Users/hiroshimatakara/Desktop/app/main.py", line 666, in handle_exception
    return jsonify(response), 500
TypeError: 'module' object is not callable

During handling of the above exception, another exception occurred:

Traceback (most recent call last):
  File "/Users/hiroshimatakara/Desktop/app/venv/lib/python3.9/site-packages/werkzeug/serving.py", line 363, in run_wsgi
    execute(self.server.app)
  File "/Users/hiroshimatakara/Desktop/app/venv/lib/python3.9/site-packages/werkzeug/serving.py", line 324, in execute
    application_iter = app(environ, start_response)
  File "/Users/hiroshimatakara/Desktop/app/venv/lib/python3.9/site-packages/flask/app.py", line 1498, in __call__
    return self.wsgi_app(environ, start_response)
  File "/Users/hiroshimatakara/Desktop/app/venv/lib/python3.9/site-packages/flask/app.py", line 1476, in wsgi_app
    response = self.handle_exception(e)
  File "/Users/hiroshimatakara/Desktop/app/venv/lib/python3.9/site-packages/flask/app.py", line 823, in handle_exception
    server_error = self.ensure_sync(handler)(server_error)
  File "/Users/hiroshimatakara/Desktop/app/main.py", line 666, in handle_exception
    return jsonify(response), 500
TypeError: 'module' object is not callable
